Workbook

Sheet compiled_data
A1: week_day | B1: date | C1: MPC MEETING | D1: official_fx_rate | E1: interbank_ovn_rate | F1: egx30 | G1: t3m | H1: t6m | I1: t1y | J1: t5y | K1: t10y | L1: fxp
A2: =TEXT(B2,"dddd") -> Sunday | B2: 40545 | C2: =IF(COUNTIF('MPC MEETINGS'!A:A,compiled_data!B2)>0,1,0) -> 0 | D2: =_xlfn.IFNA(VLOOKUP(B2,ERO!A:E,5,FALSE),_xlfn.IFNA(VLOOKUP(B2,ERO_AVG_MKT!A:E,5,FALSE),".")) -> 5.8036 | E2: =_xlfn.IFNA(VLOOKUP(B2,'IB RATES'!A:G,2,FALSE),".") -> 8.264 | F2: =_xlfn.IFNA(VLOOKUP(B2,'EGX30'!A:G,2,FALSE),".") -> 7082.4 | G2: =_xlfn.IFNA(VLOOKUP(B2,T3M!A:F,2,FALSE),".") -> . | H2: =_xlfn.IFNA(VLOOKUP(B2,T6M!A:F,2,FALSE),".") -> . | I2: =_xlfn.IFNA(VLOOKUP(B2,T1Y!A:F,2,FALSE),".") -> . | J2: =_xlfn.IFNA(VLOOKUP(B2,T5Y!A:F,2,FALSE),".") -> . | K2: =_xlfn.IFNA(VLOOKUP(B2,T10Y!A:F,2,FALSE),".") -> . | L2: =_xlfn.IFNA(VLOOKUP(B2,ERP!A:C,3,FALSE),".") -> .
A3: =TEXT(B3,"dddd") -> Monday | B3: 40546 | C3: =IF(COUNTIF('MPC MEETINGS'!A:A,compiled_data!B3)>0,1,0) -> 0 | D3: =_xlfn.IFNA(VLOOKUP(B3,ERO!A:E,5,FALSE),_xlfn.IFNA(VLOOKUP(B3,ERO_AVG_MKT!A:E,5,FALSE),".")) -> 5.8022 | E3: =_xlfn.IFNA(VLOOKUP(B3,'IB RATES'!A:G,2,FALSE),".") -> 8.261 | F3: =_xlfn.IFNA(VLOOKUP(B3,'EGX30'!A:G,2,FALSE),".") -> 7073.12 | G3: =_xlfn.IFNA(VLOOKUP(B3,T3M!A:F,2,FALSE),".") -> 9.5 | H3: =_xlfn.IFNA(VLOOKUP(B3,T6M!A:F,2,FALSE),".") -> 10.2 | I3: =_xlfn.IFNA(VLOOKUP(B3,T1Y!A:F,2,FALSE),".") -> 10.8 | J3: =_xlfn.IFNA(VLOOKUP(B3,T5Y!A:F,2,FALSE),".") -> 12.32 | K3: =_xlfn.IFNA(VLOOKUP(B3,T10Y!A:F,2,FALSE),".") -> 13 | L3: =_xlfn.IFNA(VLOOKUP(B3,ERP!A:C,3,FALSE),".") -> .
A4: =TEXT(B4,"dddd") -> Tuesday | B4: 40547 | C4: =IF(COUNTIF('MPC MEETINGS'!A:A,compiled_data!B4)>0,1,0) -> 0 | D4: =_xlfn.IFNA(VLOOKUP(B4,ERO!A:E,5,FALSE),_xlfn.IFNA(VLOOKUP(B4,ERO_AVG_MKT!A:E,5,FALSE),".")) -> 5.7966 | E4: =_xlfn.IFNA(VLOOKUP(B4,'IB RATES'!A:G,2,FALSE),".") -> 8.26 | F4: =_xlfn.IFNA(VLOOKUP(B4,'EGX30'!A:G,2,FALSE),".") -> 7200.3 | G4: =_xlfn.IFNA(VLOOKUP(B4,T3M!A:F,2,FALSE),".") -> 9.5 | H4: =_xlfn.IFNA(VLOOKUP(B4,T6M!A:F,2,FALSE),".") -> 10.2 | I4: =_xlfn.IFNA(VLOOKUP(B4,T1Y!A:F,2,FALSE),".") -> 10.8 | J4: =_xlfn.IFNA(VLOOKUP(B4,T5Y!A:F,2,FALSE),".") -> 12.32 | K4: =_xlfn.IFNA(VLOOKUP(B4,T10Y!A:F,2,FALSE),".") -> 13 | L4: =_xlfn.IFNA(VLOOKUP(B4,ERP!A:C,3,FALSE),".") -> .
A5: =TEXT(B5,"dddd") -> Wednesday | B5: 40548 | C5: =IF(COUNTIF('MPC MEETINGS'!A:A,compiled_data!B5)>0,1,0) -> 0 | D5: =_xlfn.IFNA(VLOOKUP(B5,ERO!A:E,5,FALSE),_xlfn.IFNA(VLOOKUP(B5,ERO_AVG_MKT!A:E,5,FALSE),".")) -> 5.795 | E5: =_xlfn.IFNA(VLOOKUP(B5,'IB RATES'!A:G,2,FALSE),".") -> 8.255 | F5: =_xlfn.IFNA(VLOOKUP(B5,'EGX30'!A:G,2,FALSE),".") -> 7210.41 | G5: =_xlfn.IFNA(VLOOKUP(B5,T3M!A:F,2,FALSE),".") -> . | H5: =_xlfn.IFNA(VLOOKUP(B5,T6M!A:F,2,FALSE),".") -> . | I5: =_xlfn.IFNA(VLOOKUP(B5,T1Y!A:F,2,FALSE),".") -> . | J5: =_xlfn.IFNA(VLOOKUP(B5,T5Y!A:F,2,FALSE),".") -> . | K5: =_xlfn.IFNA(VLOOKUP(B5,T10Y!A:F,2,FALSE),".") -> . | L5: =_xlfn.IFNA(VLOOKUP(B5,ERP!A:C,3,FALSE),".") -> .
A6: =TEXT(B6,"dddd") -> Thursday | B6: 40549 | C6: =IF(COUNTIF('MPC MEETINGS'!A:A,compiled_data!B6)>0,1,0) -> 0 | D6: =_xlfn.IFNA(VLOOKUP(B6,ERO!A:E,5,FALSE),_xlfn.IFNA(VLOOKUP(B6,ERO_AVG_MKT!A:E,5,FALSE),".")) -> 5.7989 | E6: =_xlfn.IFNA(VLOOKUP(B6,'IB RATES'!A:G,2,FALSE),".") -> 8.263 | F6: =_xlfn.IFNA(VLOOKUP(B6,'EGX30'!A:G,2,FALSE),".") -> 7202.58 | G6: =_xlfn.IFNA(VLOOKUP(B6,T3M!A:F,2,FALSE),".") -> 9.5 | H6: =_xlfn.IFNA(VLOOKUP(B6,T6M!A:F,2,FALSE),".") -> 10.2 | I6: =_xlfn.IFNA(VLOOKUP(B6,T1Y!A:F,2,FALSE),".") -> 10.8 | J6: =_xlfn.IFNA(VLOOKUP(B6,T5Y!A:F,2,FALSE),".") -> 12.32 | K6: =_xlfn.IFNA(VLOOKUP(B6,T10Y!A:F,2,FALSE),".") -> 13 | L6: =_xlfn.IFNA(VLOOKUP(B6,ERP!A:C,3,FALSE),".") -> .
A7: =TEXT(B7,"dddd") -> Monday | B7: 40553 | C7: =IF(COUNTIF('MPC MEETINGS'!A:A,compiled_data!B7)>0,1,0) -> 0 | D7: =_xlfn.IFNA(VLOOKUP(B7,ERO!A:E,5,FALSE),_xlfn.IFNA(VLOOKUP(B7,ERO_AVG_MKT!A:E,5,FALSE),".")) -> 5.8037 | E7: =_xlfn.IFNA(VLOOKUP(B7,'IB RATES'!A:G,2,FALSE),".") -> 8.257 | F7: =_xlfn.IFNA(VLOOKUP(B7,'EGX30'!A:G,2,FALSE),".") -> 7201.53 | G7: =_xlfn.IFNA(VLOOKUP(B7,T3M!A:F,2,FALSE),".") -> . | H7: =_xlfn.IFNA(VLOOKUP(B7,T6M!A:F,2,FALSE),".") -> . | I7: =_xlfn.IFNA(VLOOKUP(B7,T1Y!A:F,2,FALSE),".") -> . | J7: =_xlfn.IFNA(VLOOKUP(B7,T5Y!A:F,2,FALSE),".") -> 12.32 | K7: =_xlfn.IFNA(VLOOKUP(B7,T10Y!A:F,2,FALSE),".") -> 13 | L7: =_xlfn.IFNA(VLOOKUP(B7,ERP!A:C,3,FALSE),".") -> .
A8: =TEXT(B8,"dddd") -> Tuesday | B8: 40554 | C8: =IF(COUNTIF('MPC MEETINGS'!A:A,compiled_data!B8)>0,1,0) -> 0 | D8: =_xlfn.IFNA(VLOOKUP(B8,ERO!A:E,5,FALSE),_xlfn.IFNA(VLOOKUP(B8,ERO_AVG_MKT!A:E,5,FALSE),".")) -> 5.8028 | E8: =_xlfn.IFNA(VLOOKUP(B8,'IB RATES'!A:G,2,FALSE),".") -> 8.262 | F8: =_xlfn.IFNA(VLOOKUP(B8,'EGX30'!A:G,2,FALSE),".") -> 7154.7 | G8: =_xlfn.IFNA(VLOOKUP(B8,T3M!A:F,2,FALSE),".") -> 9.5 | H8: =_xlfn.IFNA(VLOOKUP(B8,T6M!A:F,2,FALSE),".") -> 10.251 | I8: =_xlfn.IFNA(VLOOKUP(B8,T1Y!A:F,2,FALSE),".") -> 10.55 | J8: =_xlfn.IFNA(VLOOKUP(B8,T5Y!A:F,2,FALSE),".") -> 12.5 | K8: =_xlfn.IFNA(VLOOKUP(B8,T10Y!A:F,2,FALSE),".") -> 13.06 | L8: =_xlfn.IFNA(VLOOKUP(B8,ERP!A:C,3,FALSE),".") -> .
A9: =TEXT(B9,"dddd") -> Wednesday | B9: 40555 | C9: =IF(COUNTIF('MPC MEETINGS'!A:A,compiled_data!B9)>0,1,0) -> 0 | D9: =_xlfn.IFNA(VLOOKUP(B9,ERO!A:E,5,FALSE),_xlfn.IFNA(VLOOKUP(B9,ERO_AVG_MKT!A:E,5,FALSE),".")) -> 5.7984 | E9: =_xlfn.IFNA(VLOOKUP(B9,'IB RATES'!A:G,2,FALSE),".") -> 8.262 | F9: =_xlfn.IFNA(VLOOKUP(B9,'EGX30'!A:G,2,FALSE),".") -> 7128.96 | G9: =_xlfn.IFNA(VLOOKUP(B9,T3M!A:F,2,FALSE),".") -> 10.32 | H9: =_xlfn.IFNA(VLOOKUP(B9,T6M!A:F,2,FALSE),".") -> 10.25 | I9: =_xlfn.IFNA(VLOOKUP(B9,T1Y!A:F,2,FALSE),".") -> 10.55 | J9: =_xlfn.IFNA(VLOOKUP(B9,T5Y!A:F,2,FALSE),".") -> 12.5 | K9: =_xlfn.IFNA(VLOOKUP(B9,T10Y!A:F,2,FALSE),".") -> 13.06 | L9: =_xlfn.IFNA(VLOOKUP(B9,ERP!A:C,3,FALSE),".") -> .
A10: =TEXT(B10,"dddd") -> Thursday | B10: 40556 | C10: =IF(COUNTIF('MPC MEETINGS'!A:A,compiled_data!B10)>0,1,0) -> 0 | D10: =_xlfn.IFNA(VLOOKUP(B10,ERO!A:E,5,FALSE),_xlfn.IFNA(VLOOKUP(B10,ERO_AVG_MKT!A:E,5,FALSE),".")) -> 5.7983 | E10: =_xlfn.IFNA(VLOOKUP(B10,'IB RATES'!A:G,2,FALSE),".") -> 8.262 | F10: =_xlfn.IFNA(VLOOKUP(B10,'EGX30'!A:G,2,FALSE),".") -> 7156.28 | G10: =_xlfn.IFNA(VLOOKUP(B10,T3M!A:F,2,FALSE),".") -> . | H10: =_xlfn.IFNA(VLOOKUP(B10,T6M!A:F,2,FALSE),".") -> . | I10: =_xlfn.IFNA(VLOOKUP(B10,T1Y!A:F,2,FALSE),".") -> . | J10: =_xlfn.IFNA(VLOOKUP(B10,T5Y!A:F,2,FALSE),".") -> . | K10: =_xlfn.IFNA(VLOOKUP(B10,T10Y!A:F,2,FALSE),".") -> . | L10: =_xlfn.IFNA(VLOOKUP(B10,ERP!A:C,3,FALSE),".") -> .
A11: =TEXT(B11,"dddd") -> Sunday | B11: 40559 | C11: =IF(COUNTIF('MPC MEETINGS'!A:A,compiled_data!B11)>0,1,0) -> 0 | D11: =_xlfn.IFNA(VLOOKUP(B11,ERO!A:E,5,FALSE),_xlfn.IFNA(VLOOKUP(B11,ERO_AVG_MKT!A:E,5,FALSE),".")) -> 5.7985 | E11: =_xlfn.IFNA(VLOOKUP(B11,'IB RATES'!A:G,2,FALSE),".") -> 8.259 | F11: =_xlfn.IFNA(VLOOKUP(B11,'EGX30'!A:G,2,FALSE),".") -> 7082.09 | G11: =_xlfn.IFNA(VLOOKUP(B11,T3M!A:F,2,FALSE),".") -> . | H11: =_xlfn.IFNA(VLOOKUP(B11,T6M!A:F,2,FALSE),".") -> . | I11: =_xlfn.IFNA(VLOOKUP(B11,T1Y!A:F,2,FALSE),".") -> . | J11: =_xlfn.IFNA(VLOOKUP(B11,T5Y!A:F,2,FALSE),".") -> . | K11: =_xlfn.IFNA(VLOOKUP(B11,T10Y!A:F,2,FALSE),".") -> . | L11: =_xlfn.IFNA(VLOOKUP(B11,ERP!A:C,3,FALSE),".") -> .
A12: =TEXT(B12,"dddd") -> Monday | B12: 40560 | C12: =IF(COUNTIF('MPC MEETINGS'!A:A,compiled_data!B12)>0,1,0) -> 0 | D12: =_xlfn.IFNA(VLOOKUP(B12,ERO!A:E,5,FALSE),_xlfn.IFNA(VLOOKUP(B12,ERO_AVG_MKT!A:E,5,FALSE),".")) -> 5.8138 | E12: =_xlfn.IFNA(VLOOKUP(B12,'IB RATES'!A:G,2,FALSE),".") -> 8.26 | F12: =_xlfn.IFNA(VLOOKUP(B12,'EGX30'!A:G,2,FALSE),".") -> 6910.53 | G12: =_xlfn.IFNA(VLOOKUP(B12,T3M!A:F,2,FALSE),".") -> 9.597 | H12: =_xlfn.IFNA(VLOOKUP(B12,T6M!A:F,2,FALSE),".") -> 9.899 | I12: =_xlfn.IFNA(VLOOKUP(B12,T1Y!A:F,2,FALSE),".") -> 10.6 | J12: =_xlfn.IFNA(VLOOKUP(B12,T5Y!A:F,2,FALSE),".") -> 12.32 | K12: =_xlfn.IFNA(VLOOKUP(B12,T10Y!A:F,2,FALSE),".") -> 13.108 | L12: =_xlfn.IFNA(VLOOKUP(B12,ERP!A:C,3,FALSE),".") -> .
A13: =TEXT(B13,"dddd") -> Tuesday | B13: 40561 | C13: =IF(COUNTIF('MPC MEETINGS'!A:A,compiled_data!B13)>0,1,0) -> 0 | D13: =_xlfn.IFNA(VLOOKUP(B13,ERO!A:E,5,FALSE),_xlfn.IFNA(VLOOKUP(B13,ERO_AVG_MKT!A:E,5,FALSE),".")) -> 5.8255 | E13: =_xlfn.IFNA(VLOOKUP(B13,'IB RATES'!A:G,2,FALSE),".") -> 8.262 | F13: =_xlfn.IFNA(VLOOKUP(B13,'EGX30'!A:G,2,FALSE),".") -> 6693.58 | G13: =_xlfn.IFNA(VLOOKUP(B13,T3M!A:F,2,FALSE),".") -> . | H13: =_xlfn.IFNA(VLOOKUP(B13,T6M!A:F,2,FALSE),".") -> 9.95 | I13: =_xlfn.IFNA(VLOOKUP(B13,T1Y!A:F,2,FALSE),".") -> 10.35 | J13: =_xlfn.IFNA(VLOOKUP(B13,T5Y!A:F,2,FALSE),".") -> . | K13: =_xlfn.IFNA(VLOOKUP(B13,T10Y!A:F,2,FALSE),".") -> . | L13: =_xlfn.IFNA(VLOOKUP(B13,ERP!A:C,3,FALSE),".") -> .
... A3179: =TEXT(B3179,"dddd") -> Thursday | B3179: 45428 | C3179: =IF(COUNTIF('MPC MEETINGS'!A:A,compiled_data!B3179)>0,1,0) -> 0 | D3179: =_xlfn.IFNA(VLOOKUP(B3179,ERO!A:E,5,FALSE),_xlfn.IFNA(VLOOKUP(B3179,ERO_AVG_MKT!A:E,5,FALSE),".")) -> 46.90365 | E3179: =_xlfn.IFNA(VLOOKUP(B3179,'IB RATES'!A:G,2,FALSE),".") -> 27.391 | F3179: =_xlfn.IFNA(VLOOKUP(B3179,'EGX30'!A:G,2,FALSE),".") -> 26142.84 | G3179: =_xlfn.IFNA(VLOOKUP(B3179,T3M!A:F,2,FALSE),".") -> 22.971 | H3179: =_xlfn.IFNA(VLOOKUP(B3179,T6M!A:F,2,FALSE),".") -> 25.645 | I3179: =_xlfn.IFNA(VLOOKUP(B3179,T1Y!A:F,2,FALSE),".") -> 26.234 | J3179: =_xlfn.IFNA(VLOOKUP(B3179,T5Y!A:F,2,FALSE),".") -> 26.08 | K3179: =_xlfn.IFNA(VLOOKUP(B3179,T10Y!A:F,2,FALSE),".") -> 26.18 | L3179: =_xlfn.IFNA(VLOOKUP(B3179,ERP!A:C,3,FALSE),".") -> 46.163
A3180: =TEXT(B3180,"dddd") -> Sunday | B3180: 45431 | C3180: =IF(COUNTIF('MPC MEETINGS'!A:A,compiled_data!B3180)>0,1,0) -> 0 | D3180: =_xlfn.IFNA(VLOOKUP(B3180,ERO!A:E,5,FALSE),_xlfn.IFNA(VLOOKUP(B3180,ERO_AVG_MKT!A:E,5,FALSE),".")) -> 46.8557 | E3180: =_xlfn.IFNA(VLOOKUP(B3180,'IB RATES'!A:G,2,FALSE),".") -> 27.385 | F3180: =_xlfn.IFNA(VLOOKUP(B3180,'EGX30'!A:G,2,FALSE),".") -> 27315.83 | G3180: =_xlfn.IFNA(VLOOKUP(B3180,T3M!A:F,2,FALSE),".") -> . | H3180: =_xlfn.IFNA(VLOOKUP(B3180,T6M!A:F,2,FALSE),".") -> . | I3180: =_xlfn.IFNA(VLOOKUP(B3180,T1Y!A:F,2,FALSE),".") -> . | J3180: =_xlfn.IFNA(VLOOKUP(B3180,T5Y!A:F,2,FALSE),".") -> . | K3180: =_xlfn.IFNA(VLOOKUP(B3180,T10Y!A:F,2,FALSE),".") -> . | L3180: .
A3181: =TEXT(B3181,"dddd") -> Monday | B3181: 45432 | C3181: =IF(COUNTIF('MPC MEETINGS'!A:A,compiled_data!B3181)>0,1,0) -> 0 | D3181: =_xlfn.IFNA(VLOOKUP(B3181,ERO!A:E,5,FALSE),_xlfn.IFNA(VLOOKUP(B3181,ERO_AVG_MKT!A:E,5,FALSE),".")) -> 46.62525 | E3181: =_xlfn.IFNA(VLOOKUP(B3181,'IB RATES'!A:G,2,FALSE),".") -> 27.365 | F3181: =_xlfn.IFNA(VLOOKUP(B3181,'EGX30'!A:G,2,FALSE),".") -> 27228.85 | G3181: =_xlfn.IFNA(VLOOKUP(B3181,T3M!A:F,2,FALSE),".") -> 25.018 | H3181: =_xlfn.IFNA(VLOOKUP(B3181,T6M!A:F,2,FALSE),".") -> 25.925 | I3181: =_xlfn.IFNA(VLOOKUP(B3181,T1Y!A:F,2,FALSE),".") -> 26.126 | J3181: =_xlfn.IFNA(VLOOKUP(B3181,T5Y!A:F,2,FALSE),".") -> 25.92 | K3181: =_xlfn.IFNA(VLOOKUP(B3181,T10Y!A:F,2,FALSE),".") -> 26 | L3181: .
A3182: =TEXT(B3182,"dddd") -> Tuesday | B3182: 45433 | C3182: =IF(COUNTIF('MPC MEETINGS'!A:A,compiled_data!B3182)>0,1,0) -> 0 | D3182: =_xlfn.IFNA(VLOOKUP(B3182,ERO!A:E,5,FALSE),_xlfn.IFNA(VLOOKUP(B3182,ERO_AVG_MKT!A:E,5,FALSE),".")) -> 46.64645 | E3182: =_xlfn.IFNA(VLOOKUP(B3182,'IB RATES'!A:G,2,FALSE),".") -> 27.325 | F3182: =_xlfn.IFNA(VLOOKUP(B3182,'EGX30'!A:G,2,FALSE),".") -> 27224.8 | G3182: =_xlfn.IFNA(VLOOKUP(B3182,T3M!A:F,2,FALSE),".") -> 25.05 | H3182: =_xlfn.IFNA(VLOOKUP(B3182,T6M!A:F,2,FALSE),".") -> 25.75 | I3182: =_xlfn.IFNA(VLOOKUP(B3182,T1Y!A:F,2,FALSE),".") -> 26.099 | J3182: =_xlfn.IFNA(VLOOKUP(B3182,T5Y!A:F,2,FALSE),".") -> 25.74 | K3182: =_xlfn.IFNA(VLOOKUP(B3182,T10Y!A:F,2,FALSE),".") -> 25.79 | L3182: .
A3183: =TEXT(B3183,"dddd") -> Wednesday | B3183: 45434 | C3183: =IF(COUNTIF('MPC MEETINGS'!A:A,compiled_data!B3183)>0,1,0) -> 0 | D3183: =_xlfn.IFNA(VLOOKUP(B3183,ERO!A:E,5,FALSE),_xlfn.IFNA(VLOOKUP(B3183,ERO_AVG_MKT!A:E,5,FALSE),".")) -> 46.81045 | E3183: =_xlfn.IFNA(VLOOKUP(B3183,'IB RATES'!A:G,2,FALSE),".") -> 27.262 | F3183: =_xlfn.IFNA(VLOOKUP(B3183,'EGX30'!A:G,2,FALSE),".") -> 27227.44 | G3183: =_xlfn.IFNA(VLOOKUP(B3183,T3M!A:F,2,FALSE),".") -> 25.885 | H3183: =_xlfn.IFNA(VLOOKUP(B3183,T6M!A:F,2,FALSE),".") -> 26.039 | I3183: =_xlfn.IFNA(VLOOKUP(B3183,T1Y!A:F,2,FALSE),".") -> 26.185 | J3183: =_xlfn.IFNA(VLOOKUP(B3183,T5Y!A:F,2,FALSE),".") -> 25.69 | K3183: =_xlfn.IFNA(VLOOKUP(B3183,T10Y!A:F,2,FALSE),".") -> 25.72 | L3183: .
A3184: =TEXT(B3184,"dddd") -> Thursday | B3184: 45435 | C3184: =IF(COUNTIF('MPC MEETINGS'!A:A,compiled_data!B3184)>0,1,0) -> 1 | D3184: =_xlfn.IFNA(VLOOKUP(B3184,ERO!A:E,5,FALSE),_xlfn.IFNA(VLOOKUP(B3184,ERO_AVG_MKT!A:E,5,FALSE),".")) -> 47.12125 | E3184: =_xlfn.IFNA(VLOOKUP(B3184,'IB RATES'!A:G,2,FALSE),".") -> 27.271 | F3184: =_xlfn.IFNA(VLOOKUP(B3184,'EGX30'!A:G,2,FALSE),".") -> 27205.14 | G3184: =_xlfn.IFNA(VLOOKUP(B3184,T3M!A:F,2,FALSE),".") -> 25.577 | H3184: =_xlfn.IFNA(VLOOKUP(B3184,T6M!A:F,2,FALSE),".") -> 25.838 | I3184: =_xlfn.IFNA(VLOOKUP(B3184,T1Y!A:F,2,FALSE),".") -> 25.89 | J3184: =_xlfn.IFNA(VLOOKUP(B3184,T5Y!A:F,2,FALSE),".") -> 25.7 | K3184: =_xlfn.IFNA(VLOOKUP(B3184,T10Y!A:F,2,FALSE),".") -> 25.73 | L3184: .
A3185: =TEXT(B3185,"dddd") -> Sunday | B3185: 45438 | C3185: =IF(COUNTIF('MPC MEETINGS'!A:A,compiled_data!B3185)>0,1,0) -> 0 | D3185: =_xlfn.IFNA(VLOOKUP(B3185,ERO!A:E,5,FALSE),_xlfn.IFNA(VLOOKUP(B3185,ERO_AVG_MKT!A:E,5,FALSE),".")) -> 46.94975 | E3185: =_xlfn.IFNA(VLOOKUP(B3185,'IB RATES'!A:G,2,FALSE),".") -> 27.253 | F3185: =_xlfn.IFNA(VLOOKUP(B3185,'EGX30'!A:G,2,FALSE),".") -> 27539.21 | G3185: =_xlfn.IFNA(VLOOKUP(B3185,T3M!A:F,2,FALSE),".") -> . | H3185: =_xlfn.IFNA(VLOOKUP(B3185,T6M!A:F,2,FALSE),".") -> . | I3185: =_xlfn.IFNA(VLOOKUP(B3185,T1Y!A:F,2,FALSE),".") -> . | J3185: =_xlfn.IFNA(VLOOKUP(B3185,T5Y!A:F,2,FALSE),".") -> . | K3185: =_xlfn.IFNA(VLOOKUP(B3185,T10Y!A:F,2,FALSE),".") -> . | L3185: .
A3186: =TEXT(B3186,"dddd") -> Monday | B3186: 45439 | C3186: =IF(COUNTIF('MPC MEETINGS'!A:A,compiled_data!B3186)>0,1,0) -> 0 | D3186: =_xlfn.IFNA(VLOOKUP(B3186,ERO!A:E,5,FALSE),_xlfn.IFNA(VLOOKUP(B3186,ERO_AVG_MKT!A:E,5,FALSE),".")) -> 47.17815 | E3186: =_xlfn.IFNA(VLOOKUP(B3186,'IB RATES'!A:G,2,FALSE),".") -> 27.257 | F3186: =_xlfn.IFNA(VLOOKUP(B3186,'EGX30'!A:G,2,FALSE),".") -> 27287.31 | G3186: =_xlfn.IFNA(VLOOKUP(B3186,T3M!A:F,2,FALSE),".") -> 24.935 | H3186: =_xlfn.IFNA(VLOOKUP(B3186,T6M!A:F,2,FALSE),".") -> 25.699 | I3186: =_xlfn.IFNA(VLOOKUP(B3186,T1Y!A:F,2,FALSE),".") -> 26.058 | J3186: =_xlfn.IFNA(VLOOKUP(B3186,T5Y!A:F,2,FALSE),".") -> 25.38 | K3186: =_xlfn.IFNA(VLOOKUP(B3186,T10Y!A:F,2,FALSE),".") -> 25.39 | L3186: .
A3187: =TEXT(B3187,"dddd") -> Tuesday | B3187: 45440 | C3187: =IF(COUNTIF('MPC MEETINGS'!A:A,compiled_data!B3187)>0,1,0) -> 0 | D3187: =_xlfn.IFNA(VLOOKUP(B3187,ERO!A:E,5,FALSE),_xlfn.IFNA(VLOOKUP(B3187,ERO_AVG_MKT!A:E,5,FALSE),".")) -> 47.51895 | E3187: =_xlfn.IFNA(VLOOKUP(B3187,'IB RATES'!A:G,2,FALSE),".") -> 27.307 | F3187: =_xlfn.IFNA(VLOOKUP(B3187,'EGX30'!A:G,2,FALSE),".") -> 27194.51 | G3187: =_xlfn.IFNA(VLOOKUP(B3187,T3M!A:F,2,FALSE),".") -> 25.022 | H3187: =_xlfn.IFNA(VLOOKUP(B3187,T6M!A:F,2,FALSE),".") -> 25.665 | I3187: =_xlfn.IFNA(VLOOKUP(B3187,T1Y!A:F,2,FALSE),".") -> 26.519 | J3187: =_xlfn.IFNA(VLOOKUP(B3187,T5Y!A:F,2,FALSE),".") -> 25.32 | K3187: =_xlfn.IFNA(VLOOKUP(B3187,T10Y!A:F,2,FALSE),".") -> 25.32 | L3187: .
A3188: =TEXT(B3188,"dddd") -> Wednesday | B3188: 45441 | C3188: =IF(COUNTIF('MPC MEETINGS'!A:A,compiled_data!B3188)>0,1,0) -> 0 | D3188: =_xlfn.IFNA(VLOOKUP(B3188,ERO!A:E,5,FALSE),_xlfn.IFNA(VLOOKUP(B3188,ERO_AVG_MKT!A:E,5,FALSE),".")) -> 47.31915 | E3188: =_xlfn.IFNA(VLOOKUP(B3188,'IB RATES'!A:G,2,FALSE),".") -> 27.386 | F3188: =_xlfn.IFNA(VLOOKUP(B3188,'EGX30'!A:G,2,FALSE),".") -> 27089.68 | G3188: =_xlfn.IFNA(VLOOKUP(B3188,T3M!A:F,2,FALSE),".") -> 23.55 | H3188: =_xlfn.IFNA(VLOOKUP(B3188,T6M!A:F,2,FALSE),".") -> 25.442 | I3188: =_xlfn.IFNA(VLOOKUP(B3188,T1Y!A:F,2,FALSE),".") -> 26.157 | J3188: =_xlfn.IFNA(VLOOKUP(B3188,T5Y!A:F,2,FALSE),".") -> 25.34 | K3188: =_xlfn.IFNA(VLOOKUP(B3188,T10Y!A:F,2,FALSE),".") -> 25.34 | L3188: .
A3189: =TEXT(B3189,"dddd") -> Thursday | B3189: 45442 | C3189: =IF(COUNTIF('MPC MEETINGS'!A:A,compiled_data!B3189)>0,1,0) -> 0 | D3189: =_xlfn.IFNA(VLOOKUP(B3189,ERO!A:E,5,FALSE),_xlfn.IFNA(VLOOKUP(B3189,ERO_AVG_MKT!A:E,5,FALSE),".")) -> 47.2815 | E3189: =_xlfn.IFNA(VLOOKUP(B3189,'IB RATES'!A:G,2,FALSE),".") -> 27.408 | F3189: =_xlfn.IFNA(VLOOKUP(B3189,'EGX30'!A:G,2,FALSE),".") -> 26922.76 | G3189: =_xlfn.IFNA(VLOOKUP(B3189,T3M!A:F,2,FALSE),".") -> 23.375 | H3189: =_xlfn.IFNA(VLOOKUP(B3189,T6M!A:F,2,FALSE),".") -> 25.242 | I3189: =_xlfn.IFNA(VLOOKUP(B3189,T1Y!A:F,2,FALSE),".") -> 26.448 | J3189: =_xlfn.IFNA(VLOOKUP(B3189,T5Y!A:F,2,FALSE),".") -> 25.29 | K3189: =_xlfn.IFNA(VLOOKUP(B3189,T10Y!A:F,2,FALSE),".") -> 25.28 | L3189: .

Sheet 2024 DEVALUATION DAY
A2: week_day | B2: date | C2: MPC MEETING | D2: official_fx_rate | E2: interbank_ovn_rate | F2: egx30 | G2: t3m | H2: t6m | I2: t1y | J2: t5y | K2: t10y | L2: fxp
A3: Tuesday | B3: 45356 | C3: 0 | D3: 30.89545 | E3: 21.669 | F3: 30668.89 | G3: 22.959 | H3: 28.108 | I3: 29.913 | J3: 27.94 | K3: 27.47 | L3: 46.468
A4: Wednesday | B4: 45357 | C4: 1 | D4: 49.5003 | E4: 26.796 | F4: 29743.11 | G4: 27.253 | H4: 28.101 | I4: 29.913 | J4: 28.35 | K4: 27.76 | L4: 52.114
A5: Thursday | B5: 45358 | C5: 0 | D5: 49.4009 | E5: 27.673 | F5: 31300.54 | G5: 27.25 | H5: 28.101 | I5: 29.912 | J5: 28.35 | K5: 27.76 | L5: 51.55
A6: Sunday | B6: 45361 | C6: 0 | D6: 49.15595 | E6: 27.645 | F6: 32919.95 | G6: . | H6: . | I6: . | J6: . | K6: . | L6: 50.653
A7: Monday | B7: 45362 | C7: 0 | D7: 49.042 | E7: 27.612 | F7: 33382.51 | G7: 27.246 | H7: 30.966 | I7: 31.821 | J7: 28.75 | K7: 28.43 | L7: 50.488
C9: 2 days diff ( march 5 - march 7) | D9: =(D5-D3)/D3 -> 0.59897007 | E9: =(E5-E3)/E3 -> 0.27707785 | F9: =(F5-F3)/F3 -> 0.020595789 | G9: =(G5-G3)/G3 -> 0.18689838 | H9: =(H7-H3)/H3 -> 0.10167924 | I9: =(I7-I3)/I3 -> 0.063784976
C10: 4 days diff ( march 5 - march 11)
C13: diff between 5th and 6th of march | D13: =(D4-D3)/D3 -> 0.60218738 | E13: =(E4-E3)/E3 -> 0.23660529 | F13: =(F4-F3)/F3 -> -0.03018629 | G13: =(G4-G3)/G3 -> 0.18702905
C14: diff between 5th and 11th of march | H14: =(H7-H3)/H3 -> 0.10167924 | I14: =(I7-I3)/I3 -> 0.063784976

Sheet MPC MEETINGS
A1: Date | B1: time | C1: mpc decesion
A2: 40570 | B2: 1 | C2: keep
A3: 40612 | B3: 2 | C3: keep
A4: 40661 | B4: 3 | C4: keep
A5: 40703 | B5: 4 | C5: keep
A6: 40745 | B6: 5 | C6: keep
A7: 40780 | B7: 6 | C7: keep
A8: 40871 | B8: 7 | C8: raise, 100bp
A9: 40941 | B9: 8 | C9: keep
A10: 40990 | B10: 9 | C10: keep
A11: 41032 | B11: 10 | C11: keep
A12: 41074 | B12: 11 | C12: keep
A13: 41116 | B13: 12 | C13: keep
... A111: 45435 | B111: 110 | C111: keep

Sheet ERO
A1: Date | B1: Currency | C1: Buy | D1: Sell | E1: Average
A2: 40545 | B2: US Dollar | C2: 5.7936 | D2: 5.8136 | E2: =AVERAGE(Official_Exchange_Rates__2[[#This Row],[Buy]:[Sell]]) -> 5.8036
A3: 40546 | B3: US Dollar | C3: 5.7922 | D3: 5.8122 | E3: =AVERAGE(Official_Exchange_Rates__2[[#This Row],[Buy]:[Sell]]) -> 5.8022
A4: 40547 | B4: US Dollar | C4: 5.7866 | D4: 5.8066 | E4: =AVERAGE(Official_Exchange_Rates__2[[#This Row],[Buy]:[Sell]]) -> 5.7966
A5: 40548 | B5: US Dollar | C5: 5.785 | D5: 5.805 | E5: =AVERAGE(Official_Exchange_Rates__2[[#This Row],[Buy]:[Sell]]) -> 5.795
A6: 40549 | B6: US Dollar | C6: 5.7889 | D6: 5.8089 | E6: =AVERAGE(Official_Exchange_Rates__2[[#This Row],[Buy]:[Sell]]) -> 5.7989
A7: 40553 | B7: US Dollar | C7: 5.7937 | D7: 5.8137 | E7: =AVERAGE(Official_Exchange_Rates__2[[#This Row],[Buy]:[Sell]]) -> 5.8037
A8: 40554 | B8: US Dollar | C8: 5.7928 | D8: 5.8128 | E8: =AVERAGE(Official_Exchange_Rates__2[[#This Row],[Buy]:[Sell]]) -> 5.8028
A9: 40555 | B9: US Dollar | C9: 5.7884 | D9: 5.8084 | E9: =AVERAGE(Official_Exchange_Rates__2[[#This Row],[Buy]:[Sell]]) -> 5.7984
A10: 40556 | B10: US Dollar | C10: 5.7883 | D10: 5.8083 | E10: =AVERAGE(Official_Exchange_Rates__2[[#This Row],[Buy]:[Sell]]) -> 5.7983
A11: 40559 | B11: US Dollar | C11: 5.7885 | D11: 5.8085 | E11: =AVERAGE(Official_Exchange_Rates__2[[#This Row],[Buy]:[Sell]]) -> 5.7985
A12: 40560 | B12: US Dollar | C12: 5.8038 | D12: 5.8238 | E12: =AVERAGE(Official_Exchange_Rates__2[[#This Row],[Buy]:[Sell]]) -> 5.8138
A13: 40561 | B13: US Dollar | C13: 5.8155 | D13: 5.8355 | E13: =AVERAGE(Official_Exchange_Rates__2[[#This Row],[Buy]:[Sell]]) -> 5.8255
... A3154: 45442 | B3154: US Dollar | C3154: 47.2136 | D3154: 47.3494 | E3154: =AVERAGE(Official_Exchange_Rates__2[[#This Row],[Buy]:[Sell]]) -> 47.2815

Sheet ERO_AVG_MKT
A1: Date | B1: Currency | C1: Buy | D1: Sell | E1: Average
A2: 41968 | B2: US Dollar | C2: 7.1446 | D2: 7.1766 | E2: =AVERAGE(Exchange_Rates[[#This Row],[Buy]:[Sell]]) -> 7.1606
A3: 41970 | B3: US Dollar | C3: 7.1446 | D3: 7.1766 | E3: =AVERAGE(Exchange_Rates[[#This Row],[Buy]:[Sell]]) -> 7.1606
A4: 41976 | B4: US Dollar | C4: 7.1443 | D4: 7.1775 | E4: =AVERAGE(Exchange_Rates[[#This Row],[Buy]:[Sell]]) -> 7.1609
A5: 41981 | B5: US Dollar | C5: 7.1446 | D5: 7.1766 | E5: =AVERAGE(Exchange_Rates[[#This Row],[Buy]:[Sell]]) -> 7.1606
A6: 41982 | B6: US Dollar | C6: 7.1446 | D6: 7.1766 | E6: =AVERAGE(Exchange_Rates[[#This Row],[Buy]:[Sell]]) -> 7.1606
A7: 41983 | B7: US Dollar | C7: 7.1446 | D7: 7.1766 | E7: =AVERAGE(Exchange_Rates[[#This Row],[Buy]:[Sell]]) -> 7.1606
A8: 41984 | B8: US Dollar | C8: 7.1446 | D8: 7.1766 | E8: =AVERAGE(Exchange_Rates[[#This Row],[Buy]:[Sell]]) -> 7.1606
A9: 41987 | B9: US Dollar | C9: 7.1431 | D9: 7.1788 | E9: =AVERAGE(Exchange_Rates[[#This Row],[Buy]:[Sell]]) -> 7.16095
A10: 41988 | B10: US Dollar | C10: 7.1431 | D10: 7.1788 | E10: =AVERAGE(Exchange_Rates[[#This Row],[Buy]:[Sell]]) -> 7.16095
A11: 41989 | B11: US Dollar | C11: 7.1431 | D11: 7.1788 | E11: =AVERAGE(Exchange_Rates[[#This Row],[Buy]:[Sell]]) -> 7.16095
A12: 41990 | B12: US Dollar | C12: 7.1431 | D12: 7.1788 | E12: =AVERAGE(Exchange_Rates[[#This Row],[Buy]:[Sell]]) -> 7.16095
A13: 41991 | B13: US Dollar | C13: 7.1431 | D13: 7.1788 | E13: =AVERAGE(Exchange_Rates[[#This Row],[Buy]:[Sell]]) -> 7.16095
... A2264: 45442 | B2264: US Dollar | C2264: 47.2271 | D2264: 47.3271 | E2264: =AVERAGE(Exchange_Rates[[#This Row],[Buy]:[Sell]]) -> 47.2771

Sheet ERP
A1: Date | B1: Official Rate | C1: Parallel Market
A2: 44927 | B2: 24.7861 | C2: 30.99
A3: 44928 | B3: 24.7861 | C3: 30.99
A4: 44929 | B4: 24.8056 | C4: 31.28
A5: 44930 | B5: 26.4853 | C5: 31.48
A6: 44931 | B6: 27.1131 | C6: 30.48
A7: 44932 | B7: 27.6256 | C7: 30.54
A8: 44933 | B8: 27.66195 | C8: 31.37
A9: 44934 | B9: 28.7307 | C9: 30.52
A10: 44935 | B10: 27.6256 | C10: 30.83
A11: 44936 | B11: 27.6983 | C11: 31.48
A12: 44937 | B12: 29.7631 | C12: 30.98
A13: 44938 | B13: 29.6367 | C13: 30.93
... A458: 45383 | B458: 47.284 | C458: 47.999
A459: 45384 | C459: 47.733
A460: 45385 | C460: 47.975
A461: 45386 | C461: 48.031
A462: 45387 | C462: 47.271
A463: 45388 | C463: 47.619
A464: 45389 | C464: 47.671
A465: 45390 | C465: 47.94
A466: 45391 | C466: 47.604
A467: 45392 | C467: 47.812
A468: 45393 | C468: 47.766
A469: 45394 | C469: 48.006
A470: 45395 | C470: 49.393
... A504: 45429 | C504: 46.165
A505: 45430
A506: 45431
A507: 45432
A508: 45433
A509: 45434
A510: 45435
A511: 45436
A512: 45437
A513: 45438
A514: 45439
A515: 45440
A516: 45441
... A518: 45443

Sheet IB RATES
A1: Date | B1: Overnight | C1: Less than a Week | D1: One Week | E1: Less than a Month | F1: One Month | G1: More than a Month
A2: 40545 | B2: 8.264 | C2: 0 | D2: 8.275 | E2: 8.307 | F2: 0 | G2: 0
A3: 40546 | B3: 8.261 | C3: 8.27 | D3: 0 | E3: 8.278 | F3: 0 | G3: 0
A4: 40547 | B4: 8.26 | C4: 0 | D4: 8.271 | E4: 0 | F4: 0 | G4: 0
A5: 40548 | B5: 8.255 | C5: 0 | D5: 0 | E5: 0 | F5: 0 | G5: 0
A6: 40549 | B6: 8.263 | C6: 0 | D6: 8.28 | E6: 0 | F6: 0 | G6: 0
A7: 40553 | B7: 8.257 | C7: 0 | D7: 0 | E7: 8.307 | F7: 8.5 | G7: 0
A8: 40554 | B8: 8.262 | C8: 0 | D8: 8.267 | E8: 8.3 | F8: 0 | G8: 8.311
A9: 40555 | B9: 8.262 | C9: 8.27 | D9: 8.27 | E9: 8.294 | F9: 0 | G9: 8.265
A10: 40556 | B10: 8.262 | C10: 0 | D10: 8.275 | E10: 8.305 | F10: 0 | G10: 0
A11: 40559 | B11: 8.259 | C11: 0 | D11: 0 | E11: 8.313 | F11: 0 | G11: 0
A12: 40560 | B12: 8.26 | C12: 0 | D12: 0 | E12: 0 | F12: 0 | G12: 0
A13: 40561 | B13: 8.262 | C13: 8.262 | D13: 0 | E13: 8.266 | F13: 0 | G13: 0
... A551: 41372 | B551: 10.071 | C551: 10.1 | D551: 10.3 | E551: 0 | F551: 0 | G551: 0
A552: 41373 | B552: =0.101*100 -> 10.1 | C552: 0 | D552: 0.103 | E552: 0.104 | F552: 0 | G552: 0
A553: 41374 | B553: =0.1*100 -> 10 | C553: 0.101 | D553: 0 | E553: 0 | F553: 0 | G553: 0
A554: 41375 | B554: =0.101*100 -> 10.1 | C554: 0 | D554: 0.102 | E554: 0.102 | F554: 0 | G554: 0
A555: 41378 | B555: =0.1*100 -> 10 | C555: 0.1 | D555: 0 | E555: 0 | F555: 0 | G555: 0
A556: 41379 | B556: =0.1*100 -> 10 | C556: 0 | D556: 0.104 | E556: 0 | F556: 0 | G556: 0
A557: 41380 | B557: =0.1*100 -> 10 | C557: 0.102 | D557: 0.103 | E557: 0.104 | F557: 0.106 | G557: 0.106
A558: 41381 | B558: 10.038 | C558: 10.1 | D558: 10.273 | E558: 10.43 | F558: 0 | G558: 0
A559: 41382 | B559: 10.056 | C559: 10.151 | D559: 0 | E559: 0 | F559: 10.49 | G559: 0
A560: 41385 | B560: 10.02 | C560: 10.095 | D560: 10.228 | E560: 10.377 | F560: 10.438 | G560: 0
A561: 41386 | B561: 9.992 | C561: 0 | D561: 10.25 | E561: 10.267 | F561: 0 | G561: 0
A562: 41387 | B562: 10.039 | C562: 10.1 | D562: 10.289 | E562: 10.347 | F562: 0 | G562: 0
A563: 41388 | B563: 10.14 | C563: 10.05 | D563: 0 | E563: 10.55 | F563: 0 | G563: 0
A564: 41392 | B564: 10.208 | C564: 10.025 | D564: 0 | E564: 10.346 | F564: 0 | G564: 0
A565: 41393 | B565: 9.985 | C565: 0 | D565: 0 | E565: 10.344 | F565: 0 | G565: 0
A566: 41394 | B566: 10.055 | C566: 0 | D566: 10.292 | E566: 10.335 | F566: 0 | G566: 0
A567: 41396 | B567: 10.235 | C567: 10.395 | D567: 10.372 | E567: 10.326 | F567: 0 | G567: 0
A568: 41401 | B568: 10.184 | C568: 10.317 | D568: 10.352 | E568: 10.5 | F568: 0 | G568: 0
A569: 41402 | B569: 10.08 | C569: 10.281 | D569: 10.5 | E569: 10.394 | F569: 0 | G569: 0
... A3263: 45442 | B3263: 27.408 | C3263: 27.25 | D3263: 0 | E3263: 0 | F3263: 0 | G3263: 0

Sheet EGX30
A1: Date | B1: Price | C1: Open | D1: High | E1: Low | F1: Vol. | G1: Change %
A2: 40545 | B2: 7082.4 | C2: 7133.25 | D2: 7134.57 | E2: 7082.02 | F2: 45.29M | G2: -0.0084
A3: 40546 | B3: 7073.12 | C3: 7086.81 | D3: 7115.51 | E3: 7064.18 | F3: 77.10M | G3: -0.0013
A4: 40547 | B4: 7200.3 | C4: 7089.75 | D4: 7200.71 | E4: 7089.73 | F4: 64.66M | G4: 0.018
A5: 40548 | B5: 7210.41 | C5: 7219.76 | D5: 7247.95 | E5: 7210.41 | F5: 54.31M | G5: 0.0014
A6: 40549 | B6: 7202.58 | C6: 7203.65 | D6: 7219.67 | E6: 7201.84 | F6: 49.07M | G6: -0.0011
A7: 40553 | B7: 7201.53 | C7: 7207.79 | D7: 7217.12 | E7: 7199.58 | F7: 70.56M | G7: -0.0001
A8: 40554 | B8: 7154.7 | C8: 7202.39 | D8: 7207.22 | E8: 7151.92 | F8: 52.00M | G8: -0.0065
A9: 40555 | B9: 7128.96 | C9: 7159.43 | D9: 7181.6 | E9: 7128.96 | F9: 56.00M | G9: -0.0036
A10: 40556 | B10: 7156.28 | C10: 7146.95 | D10: 7170.05 | E10: 7143.65 | F10: 42.98M | G10: 0.0038
A11: 40559 | B11: 7082.09 | C11: 7160.02 | D11: 7161.64 | E11: 7071.9 | F11: 47.42M | G11: -0.0104
A12: 40560 | B12: 6910.53 | C12: 7102.23 | D12: 7121.33 | E12: 6910.53 | F12: 123.00M | G12: -0.0242
A13: 40561 | B13: 6693.58 | C13: 6914.44 | D13: 6914.46 | E13: 6693.58 | F13: 101.47M | G13: -0.0314
... A2088: 43727 | B2088: 14742.07 | C2088: 14745.1 | D2088: 14753.46 | E2088: 14694.27 | F2088: 115.03M | G2088: -0.0002
A2089: 43730 | B2089: 13958.11 | C2089: 14742.07 | D2089: 14742.07 | E2089: 13958.11 | G2089: -0.0532
A2090: 43731 | B2090: 13753.19 | C2090: 13958.11 | D2090: 13972.26 | E2090: 13753.19 | F2090: 173.84M | G2090: -0.0147
A2091: 43732 | B2091: 13170.2 | C2091: 13753.19 | D2091: 13753.19 | E2091: 13169.51 | F2091: 207.77M | G2091: -0.0424
A2092: 43733 | B2092: 13594.61 | C2092: 13170.2 | D2092: 13599.74 | E2092: 13170.2 | F2092: 139.83M | G2092: 0.0322
A2093: 43734 | B2093: 13857.12 | C2093: 13594.61 | D2093: 13917.91 | E2093: 13594.61 | F2093: 177.19M | G2093: 0.0193
A2094: 43737 | B2094: 14315.79 | C2094: 13857.12 | D2094: 14385.53 | E2094: 13857.12 | F2094: 207.20M | G2094: 0.0331
A2095: 43738 | B2095: 14257.75 | C2095: 14315.79 | D2095: 14348.84 | E2095: 14223.29 | F2095: 114.92M | G2095: -0.0041
A2096: 43739 | B2096: 14496.84 | C2096: 14257.75 | D2096: 14497.21 | E2096: 14257.75 | F2096: 100.33M | G2096: 0.0168
A2097: 43740 | B2097: 14381.15 | C2097: 14496.84 | D2097: 14523.69 | E2097: 14381.15 | F2097: 109.76M | G2097: -0.008
A2098: 43741 | B2098: 14217.81 | C2098: 14381.15 | D2098: 14381.15 | E2098: 14140.09 | F2098: 140.58M | G2098: -0.0114
A2099: 43745 | B2099: 14431.72 | C2099: 14217.81 | D2099: 14436.15 | E2099: 14217.81 | F2099: 130.31M | G2099: 0.015
A2100: 43746 | B2100: 14348.57 | C2100: 14431.72 | D2100: 14465.09 | E2100: 14348.57 | F2100: 138.76M | G2100: -0.0058
A2101: 43747 | B2101: 14182.7 | C2101: 14348.57 | D2101: 14348.57 | E2101: 14180.43 | F2101: 81.75M | G2101: -0.0116
... A2141: 43804 | B2141: 13622.13 | C2141: 13635.52 | D2141: 13695.89 | E2141: 13622.13 | F2141: 61.54M | G2141: -0.001
A2142: 43807 | B2142: 13493.69 | C2142: 13622.13 | D2142: 13622.13 | E2142: 13493.66 | G2142: -0.0094
A2143: 43808 | B2143: 13442.52 | C2143: 13493.69 | D2143: 13499.49 | E2143: 13436.22 | F2143: 25.44M | G2143: -0.0038
A2144: 43809 | B2144: 13509.02 | C2144: 13442.52 | D2144: 13509.02 | E2144: 13423.59 | F2144: 45.70M | G2144: 0.0049
A2145: 43810 | B2145: 13427.22 | C2145: 13509.02 | D2145: 13521.88 | E2145: 13427.22 | F2145: 52.99M | G2145: -0.0061
A2146: 43811 | B2146: 13358.47 | C2146: 13427.22 | D2146: 13427.22 | E2146: 13353.15 | F2146: 45.94M | G2146: -0.0051
A2147: 43814 | B2147: 13433.54 | C2147: 13358.47 | D2147: 13433.54 | E2147: 13357.47 | F2147: 21.70M | G2147: 0.0056
A2148: 43815 | B2148: 13404.42 | C2148: 13433.54 | D2148: 13455.27 | E2148: 13404.24 | F2148: 41.29M | G2148: -0.0022
A2149: 43816 | B2149: 13627.19 | C2149: 13404.42 | D2149: 13627.19 | E2149: 13404.41 | F2149: 95.74M | G2149: 0.0166
A2150: 43817 | B2150: 13793.99 | C2150: 13627.19 | D2150: 13798.63 | E2150: 13627.19 | F2150: 412.01M | G2150: 0.0122
A2151: 43818 | B2151: 13837.19 | C2151: 13793.99 | D2151: 13856.67 | E2151: 13793.99 | F2151: 67.96M | G2151: 0.0031
A2152: 43821 | B2152: 13892.65 | C2152: 13837.19 | D2152: 13901.57 | E2152: 13793.47 | G2152: 0.004
A2153: 43822 | B2153: 13902.43 | C2153: 13892.65 | D2153: 13904.67 | E2153: 13873.49 | F2153: 33.21M | G2153: 0.0007
...

Sheet T3M
A1: Date | B1: Price | C1: Open | D1: High | E1: Low | F1: Change %
A2: 40546 | B2: 9.5 | C2: 9.5 | D2: 9.5 | E2: 9.5 | F2: 0
A3: 40547 | B3: 9.5 | C3: 9.5 | D3: 9.5 | E3: 9.5 | F3: 0
A4: 40549 | B4: 9.5 | C4: 9.5 | D4: 9.5 | E4: 9.5 | F4: 0
A5: 40554 | B5: 9.5 | C5: 9.5 | D5: 9.5 | E5: 9.5 | F5: 0
A6: 40555 | B6: 10.32 | C6: 10.32 | D6: 10.32 | E6: 10.32 | F6: 0.0863
A7: 40560 | B7: 9.597 | C7: 9.597 | D7: 9.597 | E7: 9.597 | F7: -0.0701
A8: 40562 | B8: 9.35 | C8: 9.35 | D8: 9.35 | E8: 9.35 | F8: -0.0257
A9: 40563 | B9: 9.35 | C9: 9.35 | D9: 9.35 | E9: 9.35 | F9: 0
A10: 40567 | B10: 9.35 | C10: 9.35 | D10: 9.35 | E10: 9.35 | F10: 0
A11: 40582 | B11: 10.8 | C11: 10.8 | D11: 10.8 | E11: 10.8 | F11: 0.1551
A12: 40595 | B12: 10.801 | C12: 10.801 | D12: 10.801 | E12: 10.801 | F12: 0.0001
A13: 40596 | B13: 10.998 | C13: 10.998 | D13: 10.998 | E13: 10.998 | F13: 0.0182
... A3523: 45443 | B3523: 23.37 | C3523: 23.548 | D3523: 24.969 | E3523: 23.37 | F3523: -0.0002

Sheet T6M
A1: Date | B1: Price | C1: Open | D1: High | E1: Low | F1: Change %
A2: 40546 | B2: 10.2 | C2: 10.2 | D2: 10.2 | E2: 10.2 | F2: 0
A3: 40547 | B3: 10.2 | C3: 10.2 | D3: 10.2 | E3: 10.2 | F3: 0
A4: 40549 | B4: 10.2 | C4: 10.2 | D4: 10.2 | E4: 10.2 | F4: 0
A5: 40554 | B5: 10.251 | C5: 10.251 | D5: 10.251 | E5: 10.251 | F5: 0.005
A6: 40555 | B6: 10.25 | C6: 10.25 | D6: 10.25 | E6: 10.25 | F6: -0.0001
A7: 40560 | B7: 9.899 | C7: 9.899 | D7: 9.899 | E7: 9.899 | F7: -0.0342
A8: 40561 | B8: 9.95 | C8: 9.95 | D8: 9.95 | E8: 9.95 | F8: 0.0052
A9: 40562 | B9: 10.2 | C9: 10.2 | D9: 10.2 | E9: 10.2 | F9: 0.0251
A10: 40563 | B10: 10.2 | C10: 10.2 | D10: 10.2 | E10: 10.2 | F10: 0
A11: 40567 | B11: 10.2 | C11: 10.2 | D11: 10.2 | E11: 10.2 | F11: 0
A12: 40583 | B12: 11.501 | C12: 11.501 | D12: 11.501 | E12: 11.501 | F12: 0.1275
A13: 40595 | B13: 11.5 | C13: 11.5 | D13: 11.5 | E13: 11.5 | F13: -0.0001
... A131: 41012 | B131: 14.76 | C131: 14.76 | D131: 14.76 | E131: 14.76 | F131: 0.004
A132: 41016 | B132: =(B133+B131)/2 -> 14.815 | C132: =(C133+C131)/2 -> 14.815 | D132: =(D133+D131)/2 -> 14.815 | E132: =(E133+E131)/2 -> 14.815 | F132: 79.8984
A133: 41017 | B133: 14.87 | C133: 14.87 | D133: 14.87 | E133: 14.87 | F133: -0.9875
A134: 41018 | B134: 14.841 | C134: 14.841 | D134: 14.841 | E134: 14.841 | F134: -0.002
A135: 41019 | B135: 14.87 | C135: 14.87 | D135: 14.87 | E135: 14.87 | F135: 0.002
A136: 41022 | B136: 14.88 | C136: 14.88 | D136: 14.88 | E136: 14.88 | F136: 0.0007
A137: 41023 | B137: 14.85 | C137: 14.85 | D137: 14.85 | E137: 14.85 | F137: -0.002
A138: 41025 | B138: 14.86 | C138: 14.86 | D138: 14.86 | E138: 14.86 | F138: 0.0007
A139: 41026 | B139: 14.86 | C139: 14.86 | D139: 14.86 | E139: 14.86 | F139: 0
A140: 41029 | B140: 15.15 | C140: 15.15 | D140: 15.15 | E140: 15.15 | F140: 0.0195
A141: 41031 | B141: 15.1 | C141: 15.1 | D141: 15.1 | E141: 15.1 | F141: -0.0033
A142: 41032 | B142: 15.2 | C142: 15.2 | D142: 15.2 | E142: 15.2 | F142: 0.0066
A143: 41033 | B143: 15.15 | C143: 15.15 | D143: 15.15 | E143: 15.15 | F143: -0.0033
A144: 41036 | B144: 15.2 | C144: 15.2 | D144: 15.2 | E144: 15.2 | F144: 0.0033
... A3514: 45443 | B3514: 25.242 | C3514: 25.442 | D3514: 25.803 | E3514: 25.242 | F3514: 0

Sheet T1Y
A1: Date | B1: Price | C1: Open | D1: High | E1: Low | F1: Change %
A2: 45443 | B2: 26.447 | C2: 26.157 | D2: 26.704 | E2: 26.157 | F2: 0
A3: 45442 | B3: 26.448 | C3: 26.157 | D3: 26.448 | E3: 26.157 | F3: 0.0111
A4: 45441 | B4: 26.157 | C4: 26.519 | D4: 26.519 | E4: 26.157 | F4: -0.0137
A5: 45440 | B5: 26.519 | C5: 26.057 | D5: 26.519 | E5: 26.057 | F5: 0.0177
A6: 45439 | B6: 26.058 | C6: 25.89 | D6: 26.058 | E6: 25.89 | F6: 0.0065
A7: 45436 | B7: 25.889 | C7: 26.186 | D7: 26.186 | E7: 25.889 | F7: 0
A8: 45435 | B8: 25.89 | C8: 26.186 | D8: 26.186 | E8: 25.89 | F8: -0.0113
A9: 45434 | B9: 26.185 | C9: 26.097 | D9: 26.185 | E9: 26.097 | F9: 0.0033
A10: 45433 | B10: 26.099 | C10: 26.126 | D10: 26.126 | E10: 26.099 | F10: -0.001
A11: 45432 | B11: 26.126 | C11: 26.234 | D11: 26.234 | E11: 26.126 | F11: -0.0042
A12: 45429 | B12: 26.235 | C12: 26.154 | D12: 26.477 | E12: 26.154 | F12: 0
A13: 45428 | B13: 26.234 | C13: 26.154 | D13: 26.234 | E13: 26.154 | F13: 0.0031
... A3449: 40546 | B3449: 10.8 | C3449: 10.8 | D3449: 10.8 | E3449: 10.8 | F3449: 0

Sheet T5Y
A1: Date | B1: Price | C1: Open | D1: High | E1: Low | F1: Change %
A2: 40546 | B2: 12.32 | C2: 12.32 | D2: 12.32 | E2: 12.32 | F2: 0
A3: 40547 | B3: 12.32 | C3: 12.32 | D3: 12.32 | E3: 12.32 | F3: 0
A4: 40549 | B4: 12.32 | C4: 12.32 | D4: 12.32 | E4: 12.32 | F4: 0
A5: 40553 | B5: 12.32 | C5: 12.32 | D5: 12.32 | E5: 12.32 | F5: 0
A6: 40554 | B6: 12.5 | C6: 12.5 | D6: 12.5 | E6: 12.5 | F6: 0.0146
A7: 40555 | B7: 12.5 | C7: 12.5 | D7: 12.5 | E7: 12.5 | F7: 0
A8: 40560 | B8: 12.32 | C8: 12.32 | D8: 12.32 | E8: 12.32 | F8: -0.0144
A9: 40562 | B9: 12.32 | C9: 12.32 | D9: 12.32 | E9: 12.32 | F9: 0
A10: 40563 | B10: 12.32 | C10: 12.32 | D10: 12.32 | E10: 12.32 | F10: 0
A11: 40567 | B11: 12.32 | C11: 12.32 | D11: 12.32 | E11: 12.32 | F11: 0
A12: 40610 | B12: 11.8 | C12: 11.8 | D12: 11.8 | E12: 11.8 | F12: -0.0422
A13: 40611 | B13: 11.8 | C13: 11.8 | D13: 11.8 | E13: 11.8 | F13: 0
... A872: 42022 | B872: 14.2 | C872: 14.2 | D872: 14.2 | E872: 14.2 | F872: 0
A873: 42023 | B873: =(B874+B872)/2 -> 14.2 | C873: 13.15 | D873: 13.15 | E873: 13.15 | F873: -0.0739
A874: 42024 | B874: 14.2 | C874: 14.2 | D874: 14.2 | E874: 14.2 | F874: 0.0798
A875: 42025 | B875: 14.2 | C875: 14.2 | D875: 14.2 | E875: 14.2 | F875: 0
A876: 42026 | B876: 14.2 | C876: 14.2 | D876: 14.2 | E876: 14.2 | F876: 0
A877: 42027 | B877: 14.11 | C877: 14.11 | D877: 14.11 | E877: 14.11 | F877: -0.0063
A878: 42030 | B878: 14.11 | C878: 14.11 | D878: 14.11 | E878: 14.11 | F878: 0
A879: 42032 | B879: 14.11 | C879: 14.11 | D879: 14.11 | E879: 14.11 | F879: 0
A880: 42033 | B880: 13.12 | C880: 13.12 | D880: 13.12 | E880: 13.12 | F880: -0.0702
A881: 42034 | B881: 13.12 | C881: 13.12 | D881: 13.12 | E881: 13.12 | F881: 0
A882: 42036 | B882: 13.12 | C882: 13.12 | D882: 13.12 | E882: 13.12 | F882: 0
A883: 42037 | B883: 13.12 | C883: 13.12 | D883: 13.12 | E883: 13.12 | F883: 0
A884: 42038 | B884: 13.12 | C884: 13.12 | D884: 13.12 | E884: 13.12 | F884: 0
A885: 42039 | B885: 13.12 | C885: 13.12 | D885: 13.12 | E885: 13.12 | F885: 0
... A3462: 45443 | B3462: 25.29 | C3462: 25.34 | D3462: 25.34 | E3462: 25.29 | F3462: 0

Sheet T10Y
A1: Date | B1: Price | C1: Open | D1: High | E1: Low | F1: Change %
A2: 40546 | B2: 13 | C2: 13 | D2: 13 | E2: 13 | F2: 0
A3: 40547 | B3: 13 | C3: 13 | D3: 13 | E3: 13 | F3: 0
A4: 40549 | B4: 13 | C4: 13 | D4: 13 | E4: 13 | F4: 0
A5: 40553 | B5: 13 | C5: 13 | D5: 13 | E5: 13 | F5: 0
A6: 40554 | B6: 13.06 | C6: 13.06 | D6: 13.06 | E6: 13.06 | F6: 0.0046
A7: 40555 | B7: 13.06 | C7: 13.06 | D7: 13.06 | E7: 13.06 | F7: 0
A8: 40560 | B8: 13.108 | C8: 13.108 | D8: 13.108 | E8: 13.108 | F8: 0.0037
A9: 40562 | B9: 13 | C9: 13 | D9: 13 | E9: 13 | F9: -0.0082
A10: 40563 | B10: 13 | C10: 13 | D10: 13 | E10: 13 | F10: 0
A11: 40567 | B11: 13 | C11: 13 | D11: 13 | E11: 13 | F11: 0
A12: 40602 | B12: 13.063 | C12: 13.063 | D12: 13.063 | E12: 13.063 | F12: 0.0048
A13: 40610 | B13: 14.288 | C13: 14.288 | D13: 14.288 | E13: 14.288 | F13: 0.0938
... A875: 42022 | B875: 15.22 | C875: 15.22 | D875: 15.22 | E875: 15.22 | F875: 0
A876: 42023 | B876: =(B877+B875)/2 -> 15.22 | C876: 14.5 | D876: 14.5 | E876: 14.5 | F876: -0.0473
A877: 42024 | B877: 15.22 | C877: 15.22 | D877: 15.22 | E877: 15.22 | F877: 0.0497
A878: 42025 | B878: 15.22 | C878: 15.22 | D878: 15.22 | E878: 15.22 | F878: 0
A879: 42026 | B879: 15.22 | C879: 15.22 | D879: 15.22 | E879: 15.22 | F879: 0
A880: 42027 | B880: 15.22 | C880: 15.22 | D880: 15.22 | E880: 15.22 | F880: 0
A881: 42030 | B881: 14.5 | C881: 14.5 | D881: 14.5 | E881: 14.5 | F881: -0.0473
A882: 42031 | B882: 15.22 | C882: 15.22 | D882: 15.22 | E882: 15.22 | F882: 0.0497
A883: 42032 | B883: 15.22 | C883: 15.22 | D883: 15.22 | E883: 15.22 | F883: 0
A884: 42033 | B884: 14.65 | C884: 14.65 | D884: 14.65 | E884: 14.65 | F884: -0.0375
A885: 42034 | B885: 14.65 | C885: 14.65 | D885: 14.65 | E885: 14.65 | F885: 0
A886: 42036 | B886: 14.65 | C886: 14.65 | D886: 14.65 | E886: 14.65 | F886: 0
A887: 42037 | B887: 14.65 | C887: 14.65 | D887: 14.65 | E887: 14.65 | F887: 0
A888: 42038 | B888: 14.65 | C888: 14.65 | D888: 14.65 | E888: 14.65 | F888: 0
... A3448: 45443 | B3448: 25.28 | C3448: 25.34 | D3448: 25.34 | E3448: 25.28 | F3448: 0
